Workbook

Sheet Introduction
B2: Introduction
B4: The examples provided in this file were scenarios performed during User Acceptance Testing in S4 HANA Q40. The scenario results have been copied from SAP HANA Q40 to the SAP training system.
B5: As Lease Accounting is a centralised process managed in BSC Manchester by the Lease Accounting Team and postings are initiated by Nakisa, there are no testing scenarios that can be reperformed end-to-end locally by markets.
B6: Entities may however use the data in this file to extract and recheck the results of UAT to understand how postings were made under each scenario and accounting approach.
B7: If you have questions, please consult your S4 Power User to understand what was performed and validated during testing
B8: For an explanation of the changes to the Lease Accounting Process under S4 (e.g. accounting approach treatment in STAT and TAX ledgers, Tax Perm Tagging for Leasing etc., please refer to the powerpoint training presentation.
B10: Please find details below explaining the data content on each tab and how to use it:
B12: SOURCE DATA
B13: Entity Accounting Approach:
B14: On this tab you can check the applicable accounting approach for the IFRS, STAT and TAX ledgers for each entity
B15: Scenarios:
B16: This tab provides you with information for all the scenarios by stages. You can check the sceanrio inputs (such as dates, currencies, contract terms etc.) for PR/PO creation, invoice/invoice plan creation and Nakisa Contract data.
... B47: On this tab you can explore different GL accounts used for leasing. This tab also includes the P&L accounts where TPT IDs will posted if applicable

Sheet Entity Accounting Approach
B2: Final Entity Configuration - S4 P40
A3: Entity number | B3: IFRS Ledger Approach | C3: Statutory Ledger Approach | D3: Tax Ledger Approach | E3: Country
A4: 1011 | B4: IFRS 16 | C4: IFRS 16 | D4: Accrual | E4: USA
A5: 1100 | B5: IFRS 16 | C5: IFRS 16 | D5: IFRS 16 | E5: Switzerland
A6: 1104 | B6: IFRS 16 | C6: IFRS 16 | D6: Accrual | E6: Cyprus
A7: 1106 | B7: IFRS 16 | C7: Accrual | D7: Accrual | E7: Germany
A8: 1107 | B8: IFRS 16 | C8: Accrual | D8: Accrual | E8: France
A9: 1114 | B9: IFRS 16 | C9: Accrual | D9: Accrual | E9: Netherlands
A10: 1116 | B10: IFRS 16 | C10: Accrual | D10: Accrual | E10: Greece
A11: 1118 | B11: IFRS 16 | C11: IFRS 16 | D11: Accrual | E11: Canada
A12: 1129 | B12: IFRS 16 | C12: IFRS 16 | D12: Accrual | E12: Malaysia
A13: 1143 | B13: IFRS 16 | C13: IFRS 16 | D13: IFRS 16 | E13: Hong Kong
A14: 1159 | B14: IFRS 16 | C14: Accrual | D14: Accrual | E14: Italy
A15: 1169 | B15: IFRS 16 | C15: Accrual | D15: Accrual | E15: Czech Republic
... A77: 2345 | B77: IFRS 16 | C77: Accrual | D77: Accrual | E77: Austria

Sheet Scenarios
B1: Nakisa Purchase Order / Invoice Creation Details
B3: 1 - Capitalised Contract | E3: 2 - Low Value Contract | H3: 3 - Short Term Contract
B5: PR/PO Creation | E5: PR/PO Creation (Framework Order / Invoice Plan) | H5: PR/PO Creation (Non-recoverable VAT)
B6: Material Group Name: | C6: =VLOOKUP(C7,'Material Groups'!$B:$C,2,0) -> LeaseBuild FixedCost | E6: Material Group Name: | F6: =VLOOKUP(F7,'Material Groups'!$B:$C,2,0) -> LeaseFrnFixt FixCost | H6: Material Group Name: | I6: LeaseVehicleFixCo/ND
B7: Material Group No: | C7: 95101111 | E7: Material Group No: | F7: 95101119 | H7: Material Group No: | I7: 95101117
B8: Vendor: | C8: Any related to Leasing | E8: Vendor: | F8: Any related to Leasing | H8: Vendor: | I8: Any related to Leasing
B9: Cost center: | C9: Any related to Leasing | E9: Cost center: | F9: Any related to Leasing | H9: Cost center: | I9: Any related to Leasing
B10: Tax code: | C10: Any fully recoverable VAT tax code | E10: Tax code: | F10: Any fully recoverable VAT tax code | H10: Tax code: | I10: Any non-recoverable VAT tax code
B11: Currency: | C11: Local currency (LC1) | E11: Currency: | F11: Local currency (LC1) | H11: Currency: | I11: Local currency (LC1)
B12: Quantity: | C12: 120 | E12: Quantity: | F12: 24 months | H12: Quantity: | I12: 9
B13: Price (ex. VAT): | C13: 7500 | E13: Price (ex. VAT): | F13: 250 | H13: Price (ex. VAT): | I13: 5000
B15: Invoice Creation (AP) | E15: Invoice Plan - No AP invoicing | H15: Invoice Creation (AP)
B16: Invoice 1 Date: | C16: 43647 | E16: Invoice 1 Date: | F16: 43647 | H16: Invoice 1 Date: | I16: 43647
B17: Invoice 1 Qty: | C17: 1 | E17: Invoice 1 Qty: | F17: 1 | H17: Invoice 1 Qty: | I17: 1
B18: Invoice 1 Price (ex. VAT): | C18: 7500 | E18: Invoice 1 Price (ex. VAT): | F18: 250 | H18: Invoice 1 Price (ex. VAT): | I18: 5000
B19: Invoice 1 PO: | C19: See PO numbers tab | E19: Invoice 1 PO: | F19: N/A | H19: Invoice 1 PO: | I19: See PO numbers tab
B20: Invoice 2 Date: | C20: 43678 | E20: Invoice 2 Date: | F20: 43678 | H20: Invoice 2 Date: | I20: 43678
B21: Invoice 2 Qty: | C21: 1 | E21: Invoice 2 Qty: | F21: 1 | H21: Invoice 2 Qty: | I21: 1
B22: Invoice 2 Price (ex. VAT): | C22: 7500 | E22: Invoice 2 Price (ex. VAT): | F22: 250 | H22: Invoice 2 Price (ex. VAT): | I22: 5000
B23: Invoice 2 PO: | C23: See PO numbers tab | E23: Invoice 2 PO: | F23: N/A | H23: Invoice 2 PO: | I23: See PO numbers tab
B25: Nakisa Contract Data | E25: Nakisa Contract Data | H25: Nakisa Contract Data
B26: Annual interest rate | C26: 0.05 | E26: Annual interest rate | F26: N/A | H26: Annual interest rate | I26: N/A
B27: Lease payment per period | C27: 7500 | E27: Lease payment per period | F27: 250 | H27: Lease payment per period | I27: 5000 + non-recoverable VAT
B28: Payment frequency | C28: Monthly | E28: Payment frequency | F28: Monthly | H28: Payment frequency | I28: Monthly
B29: Payment timing | C29: Advance | E29: Payment timing | F29: Advance | H29: Payment timing | I29: Advance
B30: First payment Date | C30: 43647 | E30: First payment Date | F30: 43647 | H30: First payment Date | I30: 43647
B31: Lease term (months) | C31: 120 | E31: Lease term (months) | F31: 24 | H31: Lease term (months) | I31: 9
B32: Lease start date | C32: 43647 | E32: Lease start date | F32: 43647 | H32: Lease start date | I32: 43647
B33: Lease end date | C33: 47299 | E33: Lease end date | F33: 44377 | H33: Lease end date | I33: 43921
B36: 4 - Prepaid Contract | E36: 5 - Contract Extension | H36: 6 - Contract Termination
B38: PR/PO Creation | E38: PR/PO Creation | H38: PR/PO Creation
B39: Material Group Name: | C39: =VLOOKUP(C40,'Material Groups'!$B:$C,2,0) -> LeaseLand FixedCost | E39: Material Group Name: | F39: =VLOOKUP(F40,'Material Groups'!$B:$C,2,0) -> LeaseVehicle FixCost | H39: Material Group Name: | I39: =VLOOKUP(I40,'Material Groups'!$B:$C,2,0) -> Lease HW Fixed Cost
B40: Material Group No: | C40: 95101113 | E40: Material Group No: | F40: 95101110 | H40: Material Group No: | I40: 95101116
B41: Vendor: | C41: Any related to Leasing | E41: Vendor: | F41: Any related to Leasing | H41: Vendor: | I41: Any related to Leasing
B42: Cost center: | C42: Any related to Leasing | E42: Cost center: | F42: Any related to Leasing | H42: Cost center: | I42: Any related to Leasing
B43: Tax code: | C43: Any fully recoverable VAT tax code | E43: Tax code: | F43: Any fully recoverable VAT tax code | H43: Tax code: | I43: Any fully recoverable VAT tax code
B44: Currency: | C44: Local currency (LC1) | E44: Currency: | F44: Local currency (LC1) | H44: Currency: | I44: Local currency (LC1)
B45: Quantity: | C45: 1 | E45: Quantity: | F45: 72 | H45: Quantity: | I45: 48
B46: Price (ex. VAT): | C46: 60000 | E46: Price (ex. VAT): | F46: 2000 | H46: Price (ex. VAT): | I46: 4000
B48: Invoice Creation (AP) | E48: Invoice Creation (AP) | H48: Invoice Creation (AP)
...

Sheet PO numbers
B1: 2 | C1: 3 | D1: 4 | E1: 5 | F1: 6 | G1: 2 | H1: 3 | I1: 4 | J1: 5 | K1: 6 | L1: 2 | M1: 3 | N1: 4 | O1: 5 | P1: 6 | Q1: 2 | R1: 3 | S1: 4 | T1: 5 | U1: 6 | V1: 2 | W1: 3 | X1: 4 | Y1: 5 | Z1: 6 | AA1: 2 | AB1: 3 | AC1: 4 | AD1: 5 | AE1: 6 | AF1: 2 | AG1: 3 | AH1: 4 | AI1: 5 | AJ1: 6
B2: 1 - Capitalised Contract | G2: 2 - Low Value Contract | L2: 3 - Short Term Contract | Q2: 4 - Prepaid Contract | V2: 5 - Contract Extension | AA2: 6 - Contract Termination | AF2: 7 - Capitalised contract - foreign currency
B3: PO Number | C3: Cost Center | D3: Profit Center | E3: Vendor No. | F3: Contract currency (DC) | G3: PO Number | H3: Cost Center | I3: Profit Center | J3: Vendor No. | K3: Contract currency (DC) | L3: PO Number | M3: Cost Center | N3: Profit Center | O3: Vendor No. | P3: Contract currency (DC) | Q3: PO Number | R3: Cost Center | S3: Profit Center | T3: Vendor No. | U3: Contract currency (DC) | V3: PO Number | W3: Cost Center | X3: Profit Center | Y3: Vendor No. | Z3: Contract currency (DC) | AA3: PO Number | AB3: Cost Center | AC3: Profit Center | AD3: Vendor No. | AE3: Contract currency (DC) | AF3: PO Number | AG3: Cost Center | AH3: Profit Center | AI3: Vendor No. | AJ3: Contract currency (DC)
A4: 1011 | B4: 4700407259 | C4: 0000039351 | D4: G043 | E4: 119862 | F4: USD | G4: 4502609384 | H4: 0000039351 | I4: G043 | J4: 119862 | K4: USD | L4: 4700407298 | M4: 0000039351 | N4: G043 | O4: 119862 | P4: USD | Q4: 4700407299 | R4: 0000039351 | S4: G043 | T4: 119862 | U4: USD | V4: 4700407300 | W4: 0000039351 | X4: G043 | Y4: 119862 | Z4: USD | AA4: 4700407301 | AB4: 0000039351 | AC4: G043 | AD4: 119862 | AE4: USD | AF4: 4700407302 | AG4: 0000039351 | AH4: G043 | AI4: 119862 | AJ4: USD
A5: 1100 | B5: 4700405599 | C5: 0000014100 | D5: CH00 | E5: 123019 | F5: CHF | G5: 4502608390 | H5: 0000014100 | I5: CH00 | J5: 123019 | K5: CHF | L5: 4700406719 | M5: 0000014302 | N5: CHP1 | O5: 56851 | P5: CHF | Q5: 4700405661 | R5: 0000014100 | S5: CH00 | T5: 123019 | U5: CHF | V5: 4700405662 | W5: 0000014100 | X5: CH00 | Y5: 123019 | Z5: CHF | AA5: 4700405664 | AB5: 0000014100 | AC5: CH00 | AD5: 123019 | AE5: CHF | AF5: 4700405707 | AG5: 0000014100 | AH5: CH00 | AI5: 123019 | AJ5: CHF
A6: 1104 | B6: 4502609416 | C6: 0000023147 | D6: CY00 | E6: 94416 | F6: EUR | G6: 4502609422 | H6: 0000023147 | I6: CY00 | J6: 94416 | K6: EUR | L6: 4502609417 | M6: 0000023147 | N6: CY00 | O6: 94416 | P6: EUR | Q6: 4502609418 | R6: 0000023147 | S6: CY00 | T6: 94416 | U6: EUR | V6: 4502609419 | W6: 0000023147 | X6: CY00 | Y6: 94416 | Z6: EUR | AA6: 4502609420 | AB6: 0000023147 | AC6: CY00 | AD6: 94416 | AE6: EUR | AF6: 4502609421 | AG6: 0000023147 | AH6: CY00 | AI6: 94416 | AJ6: EUR
A7: 1106 | B7: 4700406277 | C7: 0000022310 | D7: DE00 | E7: 41106 | F7: EUR | G7: 4502608651 | H7: 0000022464 | I7: DE00 | J7: 18213 | K7: EUR | L7: 4700406282 | M7: 0000022464 | N7: DE00 | O7: 169884 | P7: EUR | Q7: 4700406283 | R7: 0000022072 | S7: DEP1 | T7: 202972 | U7: EUR | V7: 4700406286 | W7: 0000022072 | X7: DEP1 | Y7: 17198 | Z7: EUR | AA7: 4700406328 | AB7: 0000022072 | AC7: DEP1 | AD7: 152344 | AE7: EUR | AF7: 4700406329 | AG7: 0000022072 | AH7: DEP1 | AI7: 36823 | AJ7: CHF
A8: 1107 | B8: 4700405719 | C8: 0000012506 | D8: FR00 | E8: 248244 | F8: EUR | G8: 4502608438 | H8: 0000012307 | I8: FR00 | J8: 248244 | K8: EUR | L8: 4700405763 | M8: 0000012307 | N8: FR00 | O8: 248244 | P8: EUR | Q8: 4700405921 | R8: 0000012506 | S8: FR00 | T8: 248244 | U8: EUR | V8: 4700405940 | W8: 0000012307 | X8: FR00 | Y8: 248244 | Z8: EUR | AA8: 4700405983 | AB8: 0000012307 | AC8: FR00 | AD8: 248244 | AE8: EUR | AF8: 4700407101 | AG8: 0000012307 | AH8: FR00 | AI8: 248244 | AJ8: EUR
A9: 1114 | B9: 4700405979 | C9: 0000010203 | D9: NL00 | E9: 210725 | F9: EUR | G9: 4502608501 | H9: 0000010201 | I9: NL00 | J9: 23588 | K9: EUR | L9: 4700405962 | M9: 0000010201 | N9: NL00 | O9: 23588 | P9: EUR | Q9: 4700405963 | R9: 0000010201 | S9: NL00 | T9: 23588 | U9: EUR | V9: 4502608509 | W9: 0000010201 | X9: NL00 | Y9: 23588 | Z9: EUR | AA9: 4700405971 | AB9: 0000010201 | AC9: NL00 | AD9: 23588 | AE9: EUR | AF9: 4700405964 | AG9: 0000010201 | AH9: NL00 | AI9: 23588 | AJ9: USD
A10: 1116 | B10: 4502609276 | C10: 0000034001 | D10: GR00 | E10: 131553 | F10: EUR | G10: 4502609271 | H10: 0000034001 | I10: GR00 | J10: 131553 | K10: EUR | L10: 4502609272 | M10: 0000034001 | N10: GR00 | O10: 233392 | P10: EUR | Q10: 4502609270 | R10: 0000034001 | S10: GR00 | T10: 131553 | U10: EUR | V10: 4502609275 | W10: 0000034001 | X10: GR00 | Y10: 233392 | Z10: EUR | AA10: 4502609274 | AB10: 0000034001 | AC10: GR00 | AD10: 131553 | AE10: EUR | AF10: 4502609273 | AG10: 0000034001 | AH10: GR00 | AI10: 235849 | AJ10: USD
A11: 1118 | B11: 4700406288 | C11: 0000038740 | D11: CA00 | E11: 257180 | F11: CAD | G11: 4502608653 | H11: 0000038740 | I11: CA00 | J11: 257180 | K11: CAD | L11: 4700406293 | M11: 0000038740 | N11: CA00 | O11: 166279 | P11: CAD | Q11: 4700406294 | R11: 0000038740 | S11: CA00 | T11: 257180 | U11: CAD | V11: 4700406295 | W11: 0000038740 | X11: CA00 | Y11: 166279 | Z11: CAD | AA11: 4700406296 | AB11: 0000038740 | AC11: CA00 | AD11: 257180 | AE11: CAD | AF11: 4700406301 | AG11: 0000038740 | AH11: CA00 | AI11: 257180 | AJ11: CAD
A12: 1129 | B12: 4700406198 | C12: 0000036714 | D12: MY00 | E12: 97783 | F12: MYR | G12: 4502608626 | H12: 0000036802 | I12: M015 | J12: 97783 | K12: MYR | L12: 4700406231 | M12: 0000036715 | N12: MY00 | O12: 281416 | P12: MYR | Q12: 4700406245 | R12: 0000036802 | S12: M015 | T12: 280733 | U12: MYR | V12: 4700406260 | W12: 0000036714 | X12: MY00 | Y12: 176689 | Z12: MYR | AA12: 4700406269 | AB12: 0000036802 | AC12: M015 | AD12: 257030 | AE12: MYR | AF12: 4700406273 | AG12: 0000036712 | AH12: MY00 | AI12: 156446 | AJ12: MYR
A13: 1143 | B13: 4700407127 | C13: 0000035961 | D13: M015 | E13: 279849 | F13: USD | G13: 4502609306 | H13: 0000035962 | I13: M015 | J13: 82155 | K13: USD | L13: 4700407141 | M13: 0000035962 | N13: M015 | O13: 82155 | P13: USD | Q13: 4700407149 | R13: 0000035962 | S13: M015 | T13: 82155 | U13: USD | V13: 4700407151 | W13: 0000035962 | X13: M015 | Y13: 82155 | Z13: USD | AA13: 4700407162 | AB13: 0000035962 | AC13: M015 | AD13: 82155 | AE13: USD | AF13: 4700407172 | AG13: 0000035962 | AH13: M015 | AI13: 82155 | AJ13: HKD
A14: 1159 | B14: 4700405969 | C14: 0000012710 | D14: IT00 | E14: 267241 | F14: EUR | G14: 4700406984 | H14: 0000012760 | I14: IT00 | J14: 24648 | K14: EUR | L14: 4700406069 | M14: 0000012710 | N14: IT00 | O14: 144948 | P14: EUR | Q14: 4700406577 | R14: 0000012760 | S14: IT00 | T14: 280993 | U14: EUR | V14: 4700406080 | W14: 0000012770 | X14: IT00 | Y14: 24522 | Z14: EUR | AA14: 4700406125 | AB14: 0000012760 | AC14: IT00 | AD14: 162271 | AE14: EUR | AF14: 4700406994 | AG14: 0000012760 | AH14: IT00 | AI14: 24648 | AJ14: EUR
A15: 1169 | B15: 4700405754 | C15: 0000011822 | D15: CZ00 | E15: 233854 | F15: CZK | G15: 4502608443 | H15: 0000011822 | I15: CZ00 | J15: 233854 | K15: CZK | L15: 4700405756 | M15: 0000011803 | N15: CZ00 | O15: 233854 | P15: CZK | Q15: 4700405750 | R15: 0000011803 | S15: CZ00 | T15: 21846 | U15: CZK | V15: 4700405718 | W15: 0000011803 | X15: CZ00 | Y15: 21871 | Z15: CZK | AA15: 4700405751 | AB15: 0000011803 | AC15: CZ00 | AD15: 21846 | AE15: CZK | AF15: 4700405753 | AG15: 0000011803 | AH15: CZ00 | AI15: 221565 | AJ15: EUR
A16: 1171 | B16: 4700406543 | C16: 0000013102 | D16: TRP1 | E16: 10558 | F16: TRY | G16: 4700406552 | H16: 0000013102 | I16: TRP1 | J16: 10041 | K16: TRY | L16: 4700406553 | M16: 0000013102 | N16: TRP1 | O16: 108309 | P16: TRY | Q16: 4700406555 | R16: 0000013102 | S16: TRP1 | T16: 10558 | U16: TRY | V16: 4700406556 | W16: 0000013102 | X16: TRP1 | Y16: 108309 | Z16: TRY | AA16: 4700406557 | AB16: 0000013102 | AC16: TRP1 | AD16: 10044 | AE16: TRY | AF16: 4700406559 | AG16: 0000013102 | AH16: TRP1 | AI16: 10764 | AJ16: USD
A17: 1172 | B17: 4700406534 | C17: 0000013011 | D17: TR00 | E17: 10558 | F17: TRY | G17: 4700406532 | H17: 0000013011 | I17: TR00 | J17: 10041 | K17: TRY | L17: 4700406536 | M17: 0000013011 | N17: TR00 | O17: 108309 | P17: TRY | Q17: 4700406538 | R17: 0000013011 | S17: TR00 | T17: 10558 | U17: TRY | V17: 4700406537 | W17: 0000013011 | X17: TR00 | Y17: 288597 | Z17: TRY | AA17: 4700406533 | AB17: 0000013011 | AC17: TR00 | AD17: 10044 | AE17: TRY | AF17: 4700406535 | AG17: 0000013011 | AH17: TR00 | AI17: 10764 | AJ17: USD
A18: 1175 | B18: 4700405873 | C18: 0000028711 | D18: ROP1 | E18: 60156 | F18: RON | G18: 4502608495 | H18: 0000028711 | I18: ROP1 | J18: 60156 | K18: RON | L18: 4700405903 | M18: 0000028711 | N18: ROP1 | O18: 60156 | P18: RON | Q18: 4700405907 | R18: 0000028711 | S18: ROP1 | T18: 60156 | U18: RON | V18: 4700405909 | W18: 0000028711 | X18: ROP1 | Y18: 60156 | Z18: RON | AA18: 4700405917 | AB18: 0000028711 | AC18: ROP1 | AD18: 60156 | AE18: RON | AF18: 4700405919 | AG18: 0000028711 | AH18: ROP1 | AI18: 60156 | AJ18: EUR
... A24: 1197 | B24: 4700406542 | C24: 0000046030 | D24: F020 | E24: 10558 | F24: TRY | G24: 4700406544 | H24: 0000046030 | I24: F020 | J24: 43507 | K24: TRY | L24: 4700406545 | M24: 0000046030 | N24: F020 | O24: 108309 | P24: TRY | Q24: 4700406546 | R24: 0000046030 | S24: F020 | T24: 10036 | U24: TRY | V24: 4700406548 | W24: 0000046030 | X24: F020 | Y24: 105558 | Z24: TRY | AA24: 4700406549 | AB24: 0000046030 | AC24: F020 | AD24: 11360 | AE24: TRY | AF24: 4700406550 | AG24: 0000046030 | AH24: F020 | AI24: 202913 | AJ24: EUR
A25: 1199 | B25: 4700407212 | C25: 0000028015 | D25: TZ00 | E25: 242197 | F25: TZS | G25: 4502609443 | H25: 0000028009 | I25: TZ00 | J25: 262143 | K25: TZS | L25: 4700407351 | M25: 0000028107 | N25: TZ00 | O25: 241474 | P25: TZS | Q25: 4700407392 | R25: 0000028058 | S25: TZ00 | T25: 262153 | U25: TZS | V25: 4700407357 | W25: 0000028107 | X25: TZ00 | Y25: 241474 | Z25: TZS | AA25: 4700407395 | AB25: 0000028009 | AC25: TZ00 | AD25: 243587 | AE25: TZS | AF25: 4700407397 | AG25: 0000028009 | AH25: TZ00 | AI25: 225231 | AJ25: USD
A26: 1215 | B26: 4700407132 | C26: 0000040304 | D26: TN00 | E26: 266163 | F26: TND | G26: 4502609323 | H26: 0000040304 | I26: TN00 | J26: 266163 | K26: TND | L26: 4700407228 | M26: 0000040304 | N26: TN00 | O26: 266163 | P26: TND | Q26: 4700407229 | R26: 0000040300 | S26: TN00 | T26: 266163 | U26: TND | V26: 4700407230 | W26: 0000040304 | X26: TN00 | Y26: 266163 | Z26: TND | AA26: 4700407231 | AB26: 0000040304 | AC26: TN00 | AD26: 266163 | AE26: TND | AF26: 4700407239 | AG26: 0000040300 | AH26: TN00 | AI26: 266163 | AJ26: TND
A27: 1216 | B27: 4700405697 | C27: 0000013701 | D27: ES00 | E27: 136243 | F27: EUR | G27: 4502608435 | H27: 0000013701 | I27: ES00 | J27: 273179 | K27: EUR | L27: 4700405857 | M27: 0000013810 | N27: IC00 | O27: 26048 | P27: EUR | Q27: 4700405866 | R27: 0000013701 | S27: ES00 | T27: 248388 | U27: EUR | V27: 4700405956 | W27: 0000013701 | X27: ES00 | Y27: 26048 | Z27: EUR | AA27: 4700405994 | AB27: 0000013810 | AC27: IC00 | AD27: 158284 | AE27: EUR | AF27: 4700406211 | AG27: 0000013701 | AH27: ES00 | AI27: 114319 | AJ27: EUR
A28: 1229 | B28: 4502608699 | C28: 0000027013 | D28: ZA00 | E28: 256855 | F28: ZAR | G28: 4502608718 | H28: 0000027013 | I28: ZA00 | J28: 280364 | K28: ZAR | L28: 4700406402 | M28: 0000027013 | N28: ZA00 | O28: 261396 | P28: ZAR | Q28: 4700406407 | R28: 0000027013 | S28: ZA00 | T28: 272820 | U28: ZAR | V28: 4700406412 | W28: 0000027013 | X28: ZA00 | Y28: 261396 | Z28: ZAR | AA28: 4700406415 | AB28: 0000027013 | AC28: ZA00 | AD28: 261396 | AE28: ZAR | AF28: 4700406422 | AG28: 0000027013 | AH28: ZA00 | AI28: 251084 | AJ28: USD
A29: 1245 | B29: 4700406987 | C29: 0000011471 | D29: G003 | E29: 37061 | F29: USD | G29: 4502609164 | H29: 0000011471 | I29: G003 | J29: 23588 | K29: USD | L29: 4700406980 | M29: 0000011471 | N29: G003 | O29: 23588 | P29: USD | Q29: 4700406981 | R29: 0000011471 | S29: G003 | T29: 23588 | U29: USD | V29: 4700406985 | W29: 0000011471 | X29: G003 | Y29: 23588 | Z29: USD | AA29: 4700406986 | AB29: 0000011471 | AC29: G003 | AD29: 23588 | AE29: USD | AF29: 4700406982 | AG29: 0000011471 | AH29: G003 | AI29: 23588 | AJ29: EUR
A30: 1252 | B30: 4700405858 | C30: 0000035214 | D30: TW00 | E30: 81794 | F30: TWD | G30: 4502608537 | H30: 0000035215 | I30: TW00 | J30: 195316 | K30: TWD | L30: 4700406000 | M30: 0000035210 | N30: TW00 | O30: 81837 | P30: TWD | Q30: 4700406062 | R30: 0000035210 | S30: TW00 | T30: 81794 | U30: TWD | V30: 4700406076 | W30: 0000035216 | X30: TW00 | Y30: 252552 | Z30: TWD | AA30: 4700406107 | AB30: 0000035215 | AC30: TW00 | AD30: 151915 | AE30: TWD | AF30: 4700406124 | AG30: 0000035216 | AH30: TW00 | AI30: 36335 | AJ30: USD
A31: 1253 | B31: 4700405642 | C31: 0000034501 | D31: KR00 | E31: 161411 | F31: KRW | G31: 4502608696 | H31: 0000034501 | I31: KR00 | J31: 254514 | K31: KRW | L31: 4700405744 | M31: 0000034501 | N31: KR00 | O31: 284227 | P31: KRW | Q31: 4700405743 | R31: 0000034501 | S31: KR00 | T31: 254514 | U31: KRW | V31: 4700405759 | W31: 0000034501 | X31: KR00 | Y31: 284225 | Z31: KRW | AA31: 4700405868 | AB31: 0000034501 | AC31: KR00 | AD31: 284843 | AE31: KRW | AF31: 4700405941 | AG31: 0000034501 | AH31: KR00 | AI31: 85372 | AJ31: CHF
A32: 1256 | B32: 4700405995 | C32: 0000039486 | D32: US00 | E32: 277823 | F32: USD | G32: 4502608548 | H32: 0000039486 | I32: US00 | J32: 277823 | K32: USD | L32: 4700406056 | M32: 0000039486 | N32: US00 | O32: 277823 | P32: USD | Q32: 4700406064 | R32: 0000039486 | S32: US00 | T32: 277823 | U32: USD | V32: 4700406073 | W32: 0000039486 | X32: US00 | Y32: 277823 | Z32: USD | AA32: 4700406090 | AB32: 0000039486 | AC32: US00 | AD32: 277823 | AE32: USD | AF32: 4700406117 | AG32: 0000039486 | AH32: US00 | AI32: 277823 | AJ32: USD
A33: 1270 | B33: 4700406184 | C33: 0000038125 | D33: TH00 | E33: 267944 | F33: THB | G33: 4502608631 | H33: 0000038106 | I33: TH00 | J33: 259647 | K33: THB | L33: 4700406248 | M33: 0000038110 | N33: TH00 | O33: 259647 | P33: THB | Q33: 4700406265 | R33: 0000038106 | S33: TH00 | T33: 267944 | U33: THB | V33: 4700406376 | W33: 0000038110 | X33: TH00 | Y33: 259647 | Z33: THB | AA33: 4700406401 | AB33: 0000038125 | AC33: TH00 | AD33: 246824 | AE33: THB | AF33: 4700406968 | AG33: 0000038106 | AH33: TH00 | AI33: 246824 | AJ33: THB
A34: 1275 | B34: 4700406300 | C34: 0000039900 | D34: D003 | E34: 35777 | F34: USD | G34: 4502608655 | H34: 0000039900 | I34: D003 | J34: 35777 | K34: USD | L34: 4700406302 | M34: 0000039900 | N34: D003 | O34: 244857 | P34: USD | Q34: 4700406305 | R34: 0000039900 | S34: D003 | T34: 280671 | U34: USD | V34: 4700406308 | W34: 0000039900 | X34: D003 | Y34: 280671 | Z34: USD | AA34: 4700406310 | AB34: 0000039900 | AC34: D003 | AD34: 280671 | AE34: USD | AF34: 4700406311 | AG34: 0000039900 | AH34: D003 | AI34: 280671 | AJ34: USD
A35: 1277 | B35: 4700406353 | C35: 0000037515 | D35: SG00 | E35: 235693 | F35: SGD | G35: 4502608671 | H35: 0000037515 | I35: SG00 | J35: 271443 | K35: SGD | L35: 4700406363 | M35: 0000037515 | N35: SG00 | O35: 248848 | P35: SGD | Q35: 4700406366 | R35: 0000037515 | S35: SG00 | T35: 270380 | U35: SGD | V35: 4700406369 | W35: 0000037515 | X35: SG00 | Y35: 261883 | Z35: SGD | AA35: 4700406405 | AB35: 0000037515 | AC35: SG00 | AD35: 128149 | AE35: SGD | AF35: 4700406404 | AG35: 0000037515 | AH35: SG00 | AI35: 233668 | AJ35: SGD
A36: 1279 | B36: 4700406518 | C36: 0000038406 | D36: PH00 | E36: 226160 | F36: PHP | G36: 4502608786 | H36: 0000038406 | I36: PH00 | J36: 256115 | K36: PHP | L36: 4700406515 | M36: 0000038406 | N36: PH00 | O36: 226160 | P36: PHP | Q36: 4700406516 | R36: 0000038406 | S36: PH00 | T36: 226160 | U36: PHP | V36: 4700406517 | W36: 0000038406 | X36: PH00 | Y36: 226160 | Z36: PHP | AA36: 4700406519 | AB36: 0000038406 | AC36: PH00 | AD36: 226160 | AE36: PHP | AF36: 4700406514 | AG36: 0000038406 | AH36: PH00 | AI36: 19323 | AJ36: EUR
A37: 1284 | B37: 4700407025 | C37: 0000048812 | D37: JO00 | E37: 267031 | F37: JOD | G37: 4502609240 | H37: 0000048812 | I37: JO00 | J37: 267031 | K37: JOD | L37: 4700407032 | M37: 0000048812 | N37: JO00 | O37: 267031 | P37: JOD | Q37: 4700407035 | R37: 0000048812 | S37: JO00 | T37: 267031 | U37: JOD | V37: 4700407040 | W37: 0000048812 | X37: JO00 | Y37: 267031 | Z37: JOD | AA37: 4700407041 | AB37: 0000048812 | AC37: JO00 | AD37: 267031 | AE37: JOD | AF37: 4700407045 | AG37: 0000048812 | AH37: JO00 | AI37: 258174 | AJ37: USD
A38: 1285 | B38: 4700406098 | C38: 0000038505 | D38: VN00 | E38: 235510 | F38: USD | G38: 4502608591 | H38: 0000038505 | I38: VN00 | J38: 235510 | K38: USD | L38: 4700406183 | M38: 0000038505 | N38: VN00 | O38: 235510 | P38: USD | Q38: 4700406219 | R38: 0000038505 | S38: VN00 | T38: 235510 | U38: USD | V38: 4700406232 | W38: 0000038505 | X38: VN00 | Y38: 235510 | Z38: USD | AA38: 4700406243 | AB38: 0000038505 | AC38: VN00 | AD38: 235510 | AE38: USD | AF38: 4700406246 | AG38: 0000038505 | AH38: VN00 | AI38: 235510 | AJ38: VND
A39: 1299 | B39: 4700405960 | C39: 0000023821 | D39: G003 | E39: 263180 | F39: GBP | G39: 4502608519 | H39: 0000023821 | I39: G003 | J39: 263180 | K39: GBP | L39: 4700406010 | M39: 0000023821 | N39: G003 | O39: 263180 | P39: GBP | Q39: 4700406023 | R39: 0000023821 | S39: G003 | T39: 263180 | U39: GBP | V39: 4700406034 | W39: 0000023821 | X39: G003 | Y39: 263180 | Z39: GBP | AA39: 4700406039 | AB39: 0000023821 | AC39: G003 | AD39: 263180 | AE39: GBP | AF39: 4700406041 | AG39: 0000023821 | AH39: G003 | AI39: 263180 | AJ39: GBP
A40: 1300 | B40: 4502608871 | C40: 0000037366 | D40: F002 | E40: 263861 | F40: MYR | G40: 4502608873 | H40: 0000037366 | I40: F002 | J40: 263861 | K40: MYR | L40: 4502608874 | M40: 0000037366 | N40: F002 | O40: 263861 | P40: MYR | Q40: 4700406700 | R40: 0000037366 | S40: F002 | T40: 278190 | U40: MYR | V40: 4700406702 | W40: 0000037366 | X40: F002 | Y40: 263861 | Z40: MYR | AA40: 4700406703 | AB40: 0000037366 | AC40: F002 | AD40: 263861 | AE40: MYR | AF40: 4700406704 | AG40: 0000037366 | AH40: F002 | AI40: 263861 | AJ40: MYR
A41: 1303 | B41: 4700406235 | C41: 0000010001 | D41: BE00 | E41: 228389 | F41: EUR | G41: 4502608629 | H41: 0000010001 | I41: BE00 | J41: 197638 | K41: EUR | L41: 4700406224 | M41: 0000010001 | N41: BE00 | O41: 197638 | P41: EUR | Q41: 4700406225 | R41: 0000010001 | S41: BE00 | T41: 197638 | U41: EUR | V41: 4700406234 | W41: 0000010001 | X41: BE00 | Y41: 197638 | Z41: EUR | AA41: 4700406233 | AB41: 0000010001 | AC41: BE00 | AD41: 197638 | AE41: EUR | AF41: 4700406227 | AG41: 0000010001 | AH41: BE00 | AI41: 197638 | AJ41: EUR
A42: 1311 | B42: 4700406796 | C42: 0000024314 | D42: RUP3 | E42: 15251 | F42: RUB | G42: 4700406798 | H42: 0000024314 | I42: RUP3 | J42: 14761 | K42: RUB | L42: 4700406799 | M42: 0000024314 | N42: RUP3 | O42: 135780 | P42: RUB | Q42: 4700406800 | R42: 0000024314 | S42: RUP3 | T42: 14761 | U42: RUB | V42: 4700406801 | W42: 0000024314 | X42: RUP3 | Y42: 14761 | Z42: RUB | AA42: 4700406802 | AB42: 0000024314 | AC42: RUP3 | AD42: 15251 | AE42: RUB | AF42: 4700406803 | AG42: 0000024314 | AH42: RUP3 | AI42: 15251 | AJ42: RUB
A43: 1312 | B43: 4700405784 | C43: 0000033727 | D43: M002 | E43: 198111 | F43: RSD | G43: 4502608447 | H43: 0000033727 | I43: M002 | J43: 198111 | K43: RSD | L43: 4700405786 | M43: 0000033727 | N43: M002 | O43: 198111 | P43: RSD | Q43: 4700405787 | R43: 0000033727 | S43: M002 | T43: 198111 | U43: RSD | V43: 4700405788 | W43: 0000033727 | X43: M002 | Y43: 198111 | Z43: RSD | AA43: 4700405789 | AB43: 0000033727 | AC43: M002 | AD43: 198111 | AE43: RSD | AF43: 4700405783 | AG43: 0000033727 | AH43: M002 | AI43: 132025 | AJ43: EUR
A44: 1317 | B44: 4700406147 | C44: 0000050269 | D44: NGP1 | E44: 276536 | F44: NGN | G44: 4700406148 | H44: 0000050269 | I44: NGP1 | J44: 276536 | K44: NGN | L44: 4700406154 | M44: 0000050269 | N44: NGP1 | O44: 276536 | P44: NGN | Q44: 4700406157 | R44: 0000050269 | S44: NGP1 | T44: 276536 | U44: NGN | V44: 4700406160 | W44: 0000050269 | X44: NGP1 | Y44: 276536 | Z44: NGN | AA44: 4700406166 | AB44: 0000050269 | AC44: NGP1 | AD44: 276536 | AE44: NGN | AF44: 4700406979 | AG44: 0000050247 | AH44: NG00 | AI44: 276536 | AJ44: NGN
A45: 1318 | B45: 4700406055 | C45: 0000050012 | D45: BY00 | E45: 278091 | F45: BYN | G45: 4700406833 | H45: 0000050012 | I45: BY00 | J45: 278091 | K45: EUR | L45: 4700406922 | M45: 0000050012 | N45: BY00 | O45: 278261 | P45: BYN | Q45: 4700406923 | R45: 0000050012 | S45: BY00 | T45: 278287 | U45: BYN | V45: 4700406924 | W45: 0000050012 | X45: BY00 | Y45: 278204 | Z45: BYN | AA45: 4700406925 | AB45: 0000050012 | AC45: BY00 | AD45: 278024 | AE45: BYN | AF45: 4700406833 | AG45: 0000050012 | AH45: BY00 | AI45: 278091 | AJ45: EUR
...

Sheet Asset numbers
B1: 1 - Capitalised Contract | C1: 2 - Low Value Contract | D1: 3 - Short Term Contract | E1: 4 - Prepaid Contract | F1: 5 - Contract Extension | G1: 6 - Contract Termination | H1: 7 - Capitalised contract - foreign currency
A2: 1011 | B2: 1020000000 | C2: N/A | D2: N/A | E2: 1050000000 | F2: 1070000000 | G2: 1040000000 | H2: 1060000000
A3: 1100 | B3: 1020000001 | C3: N/A | D3: N/A | E3: 1050000000 | F3: 1070000034 | G3: 1040000015 | H3: 1060000005
A4: 1104 | B4: 1020000001 | C4: N/A | D4: N/A | E4: 1050000001 | F4: 1070000006 | G4: 1040000001 | H4: 1060000001
A5: 1106 | B5: 1020000038 | C5: N/A | D5: N/A | E5: 1050000000 | F5: 1070000062 | G5: 1040000000 | H5: 1060000004
A6: 1107 | B6: 1020000004 | C6: N/A | D6: N/A | E6: 1050000000 | F6: 1070000193 | G6: 1040000000 | H6: 1060000000
A7: 1114 | B7: 1020000001 | C7: N/A | D7: N/A | E7: 1050000000 | F7: 1070000048 | G7: 1040000016 | H7: 1060000000
A8: 1116 | B8: 1020000007 | C8: N/A | D8: N/A | E8: 1050000000 | F8: 1070000075 | G8: 1040000000 | H8: 1060000000
A9: 1118 | B9: 1020000012 | C9: N/A | D9: N/A | E9: 1050000000 | F9: 1070000110 | G9: 1040000000 | H9: 1060000000
A10: 1129 | B10: 1020000020 | C10: N/A | D10: N/A | E10: 1050000000 | F10: 1070000000 | G10: 1040000005 | H10: 1060000027
A11: 1143 | B11: 1020000041 | C11: N/A | D11: N/A | E11: 1050000000 | F11: 1070000000 | G11: 1040000000 | H11: 1060000004
A12: 1159 | B12: 1020000007 | C12: N/A | D12: N/A | E12: 1050000000 | F12: 1070000041 | G12: 1040000000 | H12: 1060000000
A13: 1169 | B13: 1020000003 | C13: N/A | D13: N/A | E13: 1050000000 | F13: 1070000089 | G13: 1040000000 | H13: 1060000000
... A75: 2345 | B75: 1020000052 | C75: N/A | D75: N/A | E75: 1050000000 | F75: 1070000019 | G75: 1040000000 | H75: 1060000000

Sheet SAP Transaction Guidance
A1: Guidance - SAP transaction FAGLL03
A3: Adding multiple GL accounts
A5: Enter SAP transaction code: | B5: FAGLL03
A6: Populate all the GL accounts by clicking:
A8: Populate all the GL account in the below fields:
A34: Select the green tick once all GL accounts are populated
A36: Then execute the transaction using the button on the far right bottom:
A40: Enter unique AG and PO number
A42: In order to filter on specific contracts using their AG number or PO number follow the below steps:
A44: Enter SAP transaction code: | B44: FAGLL03
A45: Select the custom Selections from the tops of the screen:
A52: Go to the G/L Account Line Items folder on the left hand side and expand it.
A53: Then double click on the Assignment field and you will notice it pop up on the right.
A54: Populate the AG numbers and PO number in this selection
A97: Then Save the changes
A101: Changing layout (e.g. custom report fields Assignment, Reference, Profit center etc.)
A103: To change a layout when using transaction FAGLL03 follow the below steps
A105: Once you have exectued the report select the option highlighted below:
A113: The below box will pop up and you can select any of the fields from the Hidden fields column and move them to the left by clicking button
A156: Once you have chosen all the fields you require press the copy button:
A158: Your fields will now be visible in your report.
A162: Checking asset movement types
A164: Enter SAP transaction code: | B164: AW01N
A165: Populate the company code and asset number. Then press enter
A166: Change the fiscal year to: | B166: 2019
A168: At the bottom under the transactions double click on the field under the 'Ttype' heading:
A213: This takes you to the document; then click on the line with the asset number:
A239: Select the 'more' button
A281: You will then be able to see the transaction type:

Sheet UAT Test Scripts
A1: SCENARIO | B1: STEP NAME | C1: DESCRIPTION | D1: EXPECTED RESULT
A2: SCENARIO 1
A4: 01. Scenarios & Results excel file attached (refers to this file)
A6: 02. Create Purchase Requisition
A7: 1 - Capitalised Contract | B7: 00 - Open file attached in the first test script 01 | C7: Open file attached in the first test script 01. Refer to "Scenarios" tab for details to create the PR for this contract.
A8: 1 - Capitalised Contract | B8: 01 - Enter requisition details in MyShop | C8: - Input requirements into Free-text field in MyShop - Select a random local currency Vendor used currently for Leasing (ZSRM PO must be created, no invoice plan) - Select a random cost center used currently for Leasing - Select the correct Material Group relating to Fixed leasing costs as per scenario details - Select Quantity (= no. of payments) & Price (= payment amount) - Add to shopping cart | D8: - Free-text, fixed leasing material group, cost center & payment details are input correctly
A9: 1 - Capitalised Contract | B9: 02 - Finalize PR | C9: - Ensure the right Material Group and GL account assignment (243032) is selected - PR is sent to Procurement for approval - Record PR number in HPALM Result Field | D9: - Correct fixed leasing material group can be selected - GL account assignment is defaulted to 243032 - PR number recorded in Result Field
A10: 1 - Capitalised Contract | B10: 03 - PR Approval | C10: - Procurement approves PR - Approve PR and ensure it follows the defined approval hierarchy | D10: - PR is approved - PR routing follows the right approval cycle
A12: 03. Create Purchase Order
A13: 1 - Capitalised Contract | B13: 00 - Open file attached in the first test script 01 | C13: Open file attached in the first test script 01. Refer to "Scenarios" tab for details to create the PO for this contract.
A14: 1 - Capitalised Contract | B14: 01 - PO Creation | C14: - PR is reviewed and converted to a PO (ZSRM) with all the necessary items (material group, vendor, cost center, quantity, price, account assignment 243032, GR flag unticked) - PO created and saved in SAP - Record PO number in HPALM Result Field | D14: - PR converted to PO with correct material group, vendor, cost center, quantity, price, account assignment 243032 and GR flag unticked - PO created and saved in SAP - PO number recorded in HPALM Result field
A15: 1 - Capitalised Contract | B15: 02 - GR flag removed (2 way match) | C15: - Verify the system has automatically removed the GR flag for Fixed Leasing material group | D15: - GR flag automatically removed
A16: 1 - Capitalised Contract | B16: 03 - PO Tax code (VAT) | C16: - Ensure that a "fully recoverable VAT" tax code has been selected | D16: - "Fully recoverable VAT" tax code has been selected for this scenario
A18: 04.a Create contract in Nakisa - Upload Masterdata (Lease Accounting Team - detailed test scripts not shown below)
A20: 04.b Create contract in Nakisa (Lease Accounting Team - detailed test scripts not shown below)
A22: 05. Process Invoice via MIRO
A23: 1 - Capitalised Contract | B23: 00 - Open Excel file attached in the first test script 01 | C23: Open Excel file attached in the first test script 01. Refer to "Scenarios" tab for details to create the Invoice for this contract. Refer to the "PO numbers" tab for the corresponding PO number for this Scenario / Entity
A24: 1 - Capitalised Contract | B24: 01 - Invoice posting (P7) | C24: - Post Invoice via MIRO (Input details are included in the attached file, "Scenarios" tab). Please use the specific PO number, Date, Qty & Price for this scenario as per "Invoice 1 details" - PO numbers for each scenario can be found on the "PO number" tab | D24: - Book the invoice without any errors. Confirm DR posting is made to GL 243032 - Vendor invoice with reference to PO is posted according to the input data - Recoverable Input VAT not posted to GL 243032
A25: 1 - Capitalised Contract | B25: 02 - 2 way match (No GR) - (P7) | C25: - Check that there are no errors/warnings stating that a GR needs to be booked - Ensure there are no bookings to the GRIR accounts | D25: - No GR errors/warnings - No bookings the in GRIR account
A26: 1 - Capitalised Contract | B26: 03 - Invoice posting (P8) | C26: - Post Invoice via MIRO (Input details are included in the attached file, "Scenarios" tab). Please use the specific PO number, Date, Qty & Price for this scenario as per "Invoice 2 details" - PO numbers for each scenario can be found on the "PO number" tab | D26: - Book the invoice without any errors. Confirm DR posting is made to GL 243032 - Vendor invoice with reference to PO is posted according to the input data - Recoverable Input VAT not posted to GL 243032
A27: 1 - Capitalised Contract | B27: 04 - 2 way match (No GR) - (P8) | C27: - Check that there are no errors/warnings stating that a GR needs to be booked - Ensure there are no bookings to the GRIR accounts | D27: - No GR errors/warnings - No bookings the in GRIR account
A29: 06.a FI validation (IFRS 16 Accounting Approach)
A30: 1 - Capitalised Contract | B30: 01 - Scenario Postings | C30: Open file attached in the first test script 01 for details of this E2E scenario and expected postings. All entities should validate IFRS 16 postings in the IFRS ledger (0L). For the STAT and TAX ledger validation, please refer to the "Entity setup" tab for details of your entity's accounting approach. If IFRS 16 is followed for ST / TX, please also validate postings in those ledgers. In this file you will find: - PO numbers, cost centers, profit centers and Vendor numbers related to this contract - Guidance on how to extract the relevant postings from SAP - S/4 Masterdata related to Leasing
A31: 1 - Capitalised Contract | B31: 01a - Extract SAP postings | C31: - Open SAP transaction FAGLL03 - In the GL account section, enter in all the GL's to be validated for this scenario as per the Excel results file (e.g. 203020 243031, 706030...) - To filter on a particular contract using the AG_XXXX_00000X number or PO number (for GL 243031 only), use the custom selections filter and pull accross the 'assignment field' from the GL Account Line items folder - Select "All items" - this will include any items already cleared - Exectute the transaction - To change the layout, go to the "change layout function" and pull through the Cost center, Profit centre, Assignment field and any other relevant fields needed for validation. | D31: - All postings are pulled through for the relevant contracts with required validation fields
A32: 1 - Capitalised Contract | B32: 02 - Capitalisation and Liability posting (1 & 2) | C32: - Check that the Capitalisation posting 1 and Liability posting 2 in the Excel results file are performed in SAP in applicable ledgers. Ensure that the SAP document date, GL account and amounts in DC, LC1, LC2, LC3 are correct. - Confirm postings are made with doc type "AN" for Asset Posting 1 and "YN" for Liability Posting 2 - Check that Consolidation Movement Type (120) used for Asset posting - Check that the capitalisation clearing account (203031) nets off to zero in LC 1, LC2 & LC3 for this specific contract - Ensure that postings to GL accounts have the Nakisa activation group number in format (AG_XXXX_000001) populated in the SAP "Assignment" field (XXXX represents the entity number) - Check that postings have the Nakisa contract number in format (CO_XXXX_000001) in the SAP reference field | D32: - Doc type AN used for Asset posting and YN for LT Liability posting - Postings done in correct ledgers based on accounting approach with correct Movement Type - Correct date, GL account amount and currency (DC, LC1, LC2, LC3) are used - Postings have correct format AG reference in Assignment field and contract number in the SAP reference field - Account 203031 nets off to zero in LC1, LC2 & LC3 for this specific contract
A33: 1 - Capitalised Contract | B33: 03 - LT to ST Liability Transfer (4 & 10) | C33: - Check that the LT to ST transfer posting (4 & 10) in the Excel results file are performed in SAP in applicable ledgers. Ensure that the SAP document date, GL account and amounts in DC, LC1, LC2, LC3 are correct. - Confirm postings are made with doc type "YN" - Ensure that postings to GL accounts have the Nakisa activation group number in format (AG_XXXX_000001) populated in the SAP "Assignment" field (XXXX represents the entity number) - Check that postings have the Nakisa contract number in format (CO_XXXX_000001) in the SAP reference field | D33: - Doc type YN used for postings - Postings done in correct ledgers based on accounting approach - Correct date, GL account, amount and currency (DC, LC1, LC2, LC3) are used - Postings have correct format AG reference in Assignment field and contract number in the SAP reference field
A34: 1 - Capitalised Contract | B34: 04 - Interest Accrual Postings (5 & 11) | C34: - Check that the Interest accrual posting (5 & 11) in the Excel results file are performed in SAP in applicable ledgers. Ensure that the SAP document date, GL account and amounts in DC, LC1, LC2, LC3 are correct. - Confirm postings are made with doc type "YN" - Ensure that postings to GL accounts have the Nakisa activation group number in format (AG_XXXX_000001) populated in the SAP "Assignment" field (XXXX represents the entity number) - Check that postings have the Nakisa contract number in format (CO_XXXX_000001) in the SAP reference field | D34: - Doc type YN used for postings - Postings done in correct ledgers based on accounting approach - Correct date, GL account, amount and currency (DC, LC1, LC2, LC3) are used - Postings have correct format AG reference in Assignment field and contract number in the SAP reference field
A35: 1 - Capitalised Contract | B35: 05 - Payment Postings (3 & 9) | C35: - Check that the Payment posting (3 & 9) in the Excel results file are performed in SAP in applicable ledgers. Ensure that the SAP document date, GL account and amounts in DC, LC1, LC2, LC3 are correct. - Confirm postings are made with doc type "YN" - Ensure that postings to GL account 243031 have the Purchase Order number populated in the SAP "Assignment" field - Ensure that postings to GL account 243040 / 243030 have the Nakisa activation group number in format (AG_XXXX_000001) populated in the SAP "Assignment" field (XXXX represents the entity number) | D35: - Doc type YN used for postings - Postings done in correct ledgers based on accounting approach - Correct date, GL account, amount and currency (DC, LC1, LC2, LC3) are used - Postings to account 243031 have PO number in Assignment field - Postings to account 243040 / 243030 have correct format AG reference in Assignment field
A36: 1 - Capitalised Contract | B36: 06 - AP: invoice booking (6 & 12) / invoice reposting (7 & 13) | C36: - Ensure that invoice posting 6 & 12 and invoice reposting 7 & 13 in the Excel results file are performed in SAP in applicable ledgers. Ensure that the SAP document date, GL account and amounts in DC, LC1, LC2, LC3 are correct. - Confirm that posting 6 and 12 are made with doc type "RE" - Confirm that posting 7 and 13 are made with doc type "F1" - Ensure that postings to GL account 243031 / 243032 have the Purchase Order number populated in the SAP "Assignment" field - Check that technical lease clearing account 243032 nets off to zero in LC1, LC2 and LC3 - Based on the tax code in the PO, check that recoverable VAT is correctly excluded from the invoice amount posted to account 243031 / 243032 | D36: - Correct Doc types used - Correct date, GL account, amount and currency (DC, LC1, LC2, LC3) are used - Postings to accounts 243031 / 243032 have PO number in Assignment field - Technical lease clearing account 243032 nets off to zero in LC1, LC2 and LC3 - Recoverable VAT excluded from account 243031/243032 when invoice is posted
A37: 1 - Capitalised Contract | B37: 07 - Depreciation (8 & 14) | C37: - Check that Depreciation posting 8 and 14 in the Excel results file are performed in SAP in applicable ledgers. Ensure that the SAP document date, GL account and amounts in DC, LC1, LC2, LC3 are correct. - Confirm postings are made with doc type "AF" - Check that Consolidation Movement Type (220) is used for Accumulated depreciation posting | D37: - Doc type AF used for postings - Postings done in correct ledgers based on accounting approach with correct Movement Type - Correct date, GL account, amount and currency (DC, LC1, LC2, LC3) are used
A38: 1 - Capitalised Contract | B38: 08 - Clearing | C38: - GL 243040, 243031 and 203031 are cleared by the Lease Accounting Team - Ensure that for contracts paid in arrears GL 243040 is cleared during the same month. For those paid in advance the interest accrued should be cleared in the following month. - For GL 243031 ensure that the invoice booked for the period has been cleared with the payment booked by nakisa for the same period - Ensure that GL 203031 is cleared each month - the asset and liability booking should match | D38: - All 3 GL's have been cleared with the correct items matching off - Any variances in LC1, LC2 and LC3 have been booked to the correct RFX lease liability accounts (727105 / 728005)
A40: 06.b FI validation (Accrual Accounting Approach)
A41: 1 - Capitalised Contract | B41: 01 - Scenario Postings | C41: Open file attached in the first test script 01 for details of this E2E scenario and expected postings. Accrual accounting approach only applies to the ST / TX ledger, IFRS ledger 0L will always contain IFRS 16 postings. For the STAT and TAX ledger validation, please refer to the "Entity setup" tab for details of your entity's accounting approach and validate postings in the ledgers where Accrual accounting is followed. In this file you will find: - PO numbers, cost centers, profit centers and Vendor numbers related to this contract - Guidance on how to extract the relevant postings from SAP - S/4 Masterdata related to Leasing
A42: 1 - Capitalised Contract | B42: 01a - Extract SAP postings | C42: - Open SAP transaction FAGLL03 - In the GL account section, enter in all the GL's to be validated for this scenario as per the Excel results file (e.g. 203020 243031, 706030...) - To filter on a particular contract using the AG_XXXX_00000X number or PO number (for GL 243031 only), use the custom selections filter and pull accross the 'assignment field' from the GL Account Line items folder - Select "All items" - this will include any items already cleared - Exectute the transaction - To change the layout, go to the "change layout function" and pull through the Cost center, Profit centre, Assignment field and any other relevant fields needed for validation. | D42: - All postings are pulled through for the relevant contracts with required validation fields
A43: 1 - Capitalised Contract | B43: 02 - Lease expense accrual postings (1 & 4) | C43: - Ensure that P&L accrual postings 1 and 4 in the Excel results file are performed in SAP in applicable ledgers. Ensure that the SAP document date, GL account and amounts in DC, LC1, LC2, LC3 are correct. - Confirm postings are made with doc type "YL" - Ensure that postings to GL account 243031 have the Purchase Order number populated in the SAP "Assignment" field - Ensure that postings to ST/TX GL account 5340XX have the Nakisa activation group number in format (AG_XXXX_000001) populated in the SAP "Assignment" field (XXXX represents the entity number) | D43: - Doc type YL used - Correct date, GL account, amount and currency (DC, LC1, LC2, LC3) are used - Postings have correct format AG reference in Assignment field - Check that correct ST/TX Lease expense accrual account (by asset class) is used
A44: 1 - Capitalised Contract | B44: 03 - AP: invoice booking (2 & 5) / invoice reposting (3 & 6) | C44: - Ensure that invoice posting 2 & 5 and invoice reposting 3 & 6 in the Excel results file are performed in SAP in applicable ledgers. Ensure that the SAP document date, GL account and amounts in DC, LC1, LC2, LC3 are correct. - Confirm that posting 2 and 5 are made with doc type "RE" - Confirm that posting 3 and 6 are made with doc type "F1" - Ensure that postings to GL account 243031 / 243032 have the Purchase Order number populated in the SAP "Assignment" field - Check that technical lease clearing account 243032 nets off to zero in LC1, LC2 & LC3 - Based on the tax code in the PO, check that recoverable VAT is correctly excluded from the invoice amount posted to account 243031/243032 | D44: - Correct Doc types used - Correct date, GL account, amount and currency (DC, LC1, LC2, LC3) are used - Postings to accounts 243031 / 243032 have PO number in Assignment field - Technical lease clearing account 243032 nets off to zero in LC1, LC2 and LC3 - Recoverable VAT excluded from account 243031/243032 when invoice is posted
A45: 1 - Capitalised Contract | B45: 04 - Clearing | C45: - GL 243031 is cleared by the Lease Accounting Team - Ensure that the invoice booked for the period has been cleared with the payment booked by Nakisa for the same period | D45: - GL 243031 is cleared with the correct items matching off - Any variances in LC1, LC2 and LC3 have been automatically to the correct RFX lease liability accounts (727105 / 728005)
A47: 06.c FI validation (IR Accounting Approach)
A48: 1 - Capitalised Contract | B48: 01 - Scenario Postings | C48: Open file attached in the first test script 01 for details of this E2E scenario and expected postings. Invoice Receipt accounting approach only applies to the ST / TX ledger, IFRS ledger 0L will always contain IFRS 16 postings. For the STAT and TAX ledger validation, please refer to the "Entity setup" tab for details of your entity's accounting approach and validate postings in the ledgers where Invoice Receipt accounting is followed. In this file you will find: - PO numbers, cost centers, profit centers and Vendor numbers related to this contract - Guidance on how to extract the relevant postings from SAP - S/4 Masterdata related to Leasing
A49: 1 - Capitalised Contract | B49: 01a - Extract SAP postings | C49: - Open SAP transaction FAGLL03 - In the GL account section, enter in all the GL's to be validated for this scenario as per the Excel results file (e.g. 203020 243031, 706030...) - To filter on a particular contract using the AG_XXXX_00000X number or PO number (for GL 243031 only), use the custom selections filter and pull accross the 'assignment field' from the GL Account Line items folder - Select "All items" - this will include any items already cleared - Exectute the transaction - To change the layout, go to the "change layout function" and pull through the Cost center, Profit centre, Assignment field and any other relevant fields needed for validation. | D49: - All postings are pulled through for the relevant contracts with required validation fields
...

Sheet 1 - Capitalised Contract
C1: 1 - Capitalised Contract | BB1: Advance
BB2: Arrears
C3: Asset class name | E3: Buildings
C4: Asset class no. | E4: 103020
C5: Material group name | E5: =VLOOKUP(E6,'Material Groups'!$B:$C,2,0) -> LeaseBuild FixedCost | F5: =VLOOKUP(F6,'Material Groups'!$B:$C,2,0) -> #N/A
C6: Material group no. | E6: 95101111
C7: Shopping cart number
C8: PR number
C9: PO no.
C10: Vendor ID
C11: Invoice no.
C12: Annual interest rate | F12: 0.05
C13: Monthly interest rate | F13: =(1+F12)^(1/12)-1 -> 0.0040741238
C14: Lease payment per period (excl. VAT) | F14: 7500
C15: Payment frequency | F15: Monthly
C16: Payment timing | F16: Advance
C17: First payment Date | F17: 43647
C18: Lease term (months) | F18: 120
C19: Lease start date | F19: 43647
C20: Lease end date | F20: 47299
C21: Calculated NPV | F21: -710056.42
C22: Useful life (UL) of the asset (years) | F22: 50 | R22: IFRS 16 Approach
C23: Lower UL / contract duration (Months) | F23: =IF(F18<(F22*12),F18,F22*12) -> 120 | G23: for depreciation | R23: All amounts below are in contract currency (DC)
R24: Please check LC2, LC3 FX posting conversion where applicable | AA24: Asset class name | AC24: Buildings
W25: SAP Posting date | AA25: Asset class no. | AC25: 103020
R26: Description | W26: P7 | Y26: P8 | AA26: Material group name | AC26: LeaseBuild FixedCost
R27: Initial posting: recognition of assets | V27: 1 | W27: =$D$38 -> 43647 | Y27: - | AA27: Material group no. | AC27: 95101111
I28: LEASE LIABILITY | N28: RIGHT OF USE ASSET | R28: Initial posting: recognition of liability | V28: 2 | W28: =$D$38 -> 43647 | AA28: Lease payment per period (excl. VAT) | AD28: 7500
H29: Inception | L29: DR 203031(BS) | N29: Dr 203020 (BS) | R29: Payment by Nakisa | V29: 3 | W29: =$D$38 -> 43647 | X29: 9 | Y29: =$D$39 -> 43678 | AA29: Payment frequency | AD29: Monthly
L30: CR 262530 (BS) | N30: CR 203031 (BS) | R30: LT liability to ST liability reclass | V30: 4 | W30: =$E$38 -> 43677 | X30: 10 | Y30: =$E$39 -> 43708 | AA30: Payment timing | AD30: Advance
H31: Monthly Acc. | I31: DR 706030 (PL) | K31: DR 262530 (BS) | L31: DR 262530 (BS) | O31: DR 534080 (PL) | P31: DR 534080 (PL) | R31: Interest accrual | V31: 5 | W31: =$E$38 -> 43677 | X31: 11 | Y31: =$E$39 -> 43708 | AA31: Lease term (months) | AD31: 120
I32: CR 243040 (BS) | K32: CR 243030 (BS) | L32: CR 243030 (BS) | O32: CR 211520 (BS) | P32: CR 211520 (BS) | R32: AP: invoice booking | V32: 6 | W32: =$D$38 -> 43647 | X32: 12 | Y32: =$D$39 -> 43678 | AA32: Lease start date | AD32: 43647
H33: Payment | I33: DR 243040 (BS) | K33: DR 243030 (BS) | R33: Automated reposting of AP | V33: 7 | W33: =$D$38 -> 43647 | X33: 13 | Y33: =$D$39 -> 43678 | AA33: Lease end date | AD33: 47299
I34: CR 243031 (BS) | K34: CR 243031 (BS) | R34: Depreciation run | V34: 8 | W34: =$E$38 -> 43677 | X34: 14 | Y34: =$E$39 -> 43708 | AA34: Calculated NPV | AD34: -710056.42
B36: Days | C36: Period | D36: Start Date | E36: End Date | F36: Opening Lease Liability (Principal) | G36: Total Repayment | H36: Principal repayment | I36: Interest (PL) 706030 | J36: Closing Lease Liability (Principal) | K36: ST Liability (BS) 243030 | L36: LT Liability (BS) 262530 | N36: Right of Use Asset (BS) | O36: Accumulated Depreciation (BS) | P36: Depreciation (PL) 534080
R37: Leasing ROU - Building 203020 (BS) | W37: Capitalization clearing (203031) | AB37: Lease LT Liability (262530)
B38: =E38-D38+1 -> 31 | C38: 1 | D38: =F19 -> 43647 | E38: =EOMONTH(D38,0) -> 43677 | F38: =F21 -> -710056.42 | G38: =$F$14 -> 7500 | H38: =F14 -> 7500 | I38: =(F38+G38)*F12/12 -> -2927.3184 | J38: =SUM(F38,H38) -> -702556.42 | K38: =J38-J50 -> -56147.296 | L38: =J38-K38 -> -646409.12 | N38: =IF(C38>$F$23,0,-$F$38) -> 710056.42 | O38: =-P38 -> -5917.1368 | P38: =N38/$F$23 -> 5917.1368 | R38: 1 | S38: =N38 -> 710056.42 | W38: 2 | X38: =AD38 -> 710056.42 | Y38: =S38 -> 710056.42 | Z38: 1 | AB38: 4 | AC38: =SUM(H38:H50) -> 63647.296 | AD38: =-F38 -> 710056.42 | AE38: 2
B39: =E39-D39+1 -> 31 | C39: 2 | D39: =EDATE(D38,1) -> 43678 | E39: =EOMONTH(D39,0) -> 43708 | F39: =J38 -> -702556.42 | G39: =$F$14 -> 7500 | H39: =G39+I38 -> 4572.6816 | I39: =(F39+G39+I38)*$F$12/12 -> -2908.2656 | J39: =SUM(F39,H39) -> -697983.74 | K39: =J39-J51 -> -56381.243 | L39: =J39-K39 -> -641602.49 | N39: =IF(C39>$F$23,0,-$F$38) -> 710056.42 | O39: =IF(N39=0,0,O38-P39) -> -11834.274 | P39: =N39/$F$23 -> 5917.1368 | AB39: 10 | AC39: =AD44 -> 4806.6287
B40: =E40-D40+1 -> 30 | C40: 3 | D40: =EDATE(D39,1) -> 43709 | E40: =EOMONTH(D40,0) -> 43738 | F40: =J39 -> -697983.74 | G40: =$F$14 -> 7500 | H40: =G40+I39 -> 4591.7344 | I40: =(F40+G40+I39)*$F$12/12 -> -2889.1333 | J40: =SUM(F40,H40) -> -693392 | K40: =J40-J52 -> -56616.165 | L40: =J40-K40 -> -636775.84 | N40: =IF(C40>$F$23,0,-$F$38) -> 710056.42 | O40: =IF(N40=0,0,O39-P40) -> -17751.41 | P40: =N40/$F$23 -> 5917.1368
B41: =E41-D41+1 -> 31 | C41: 4 | D41: =EDATE(D40,1) -> 43739 | E41: =EOMONTH(D41,0) -> 43769 | F41: =J40 -> -693392 | G41: =$F$14 -> 7500 | H41: =G41+I40 -> 4610.8667 | I41: =(F41+G41+I40)*$F$12/12 -> -2869.9214 | J41: =SUM(F41,H41) -> -688781.14 | K41: =J41-J53 -> -56852.066 | L41: =J41-K41 -> -631929.07 | N41: =IF(C41>$F$23,0,-$F$38) -> 710056.42 | O41: =IF(N41=0,0,O40-P41) -> -23668.547 | P41: =N41/$F$23 -> 5917.1368
...

Sheet 2 - Low Value Contract
C1: 2 - Low Value Contract | BB1: Advance
C3: IFRS 16 Approach
C4: All amounts below are in contract currency (DC)
C5: Please check LC2, LC3 FX posting conversion where applicable | J5: Lease payment per period (excl. VAT) | L5: 250
F6: SAP Posting date | J6: Payment frequency | L6: Monthly
C7: Description | F7: P7 | H7: P8 | J7: Payment timing | L7: Advance
C8: Payment by Nakisa | E8: 1 | F8: 43647 | G8: 5 | H8: 43678 | J8: First payment Date | L8: 43647
C9: Invoice booking | E9: 2 | F9: 43647 | G9: 6 | H9: 43678 | J9: Lease term (months) | L9: 24
C10: Automated reposting of Invoice | E10: 3 | F10: 43647 | G10: 7 | H10: 43678 | J10: Lease start date | L10: 43647
C11: Monthly Exempt Lease Posting | E11: 4 | F11: 43677 | G11: 8 | H11: 43708 | J11: Lease end date | L11: 44377
C14: Exempt Lease - Low Value (P&L) (534090) | H14: Prepaid rent (BS) - (167021)
C15: 4 | D15: =L5 -> 250 | H15: 1 | I15: =E20 -> 250 | J15: =D15 -> 250 | K15: 4
C16: 8 | D16: =L5 -> 250 | H16: 5 | I16: =E21 -> 250 | J16: =D16 -> 250 | K16: 8
C19: Invoice Clearing Leasing (243031) | H19: Invoice Clearing Leasing - Technical (243032)
C20: 3 | D20: =L5 -> 250 | E20: =L5 -> 250 | F20: 1 | H20: 2 | I20: =E25-I25 -> 250 | J20: =D20 -> 250 | K20: 3
C21: 7 | D21: =L5 -> 250 | E21: =L5 -> 250 | F21: 5 | H21: 6 | I21: =E26-I26 -> 250 | J21: =D21 -> 250 | K21: 7
C24: Accounts Payable* | H24: Input VAT (example - different by entity)
E25: =L5*1.2 -> 300 | F25: 2 | H25: 2 | I25: =E25*20/120 -> 50
E26: =L5*1.2 -> 300 | F26: 6 | H26: 6 | I26: =E26*20/120 -> 50
C29: Accrual Approach
C30: Lease expense postings for Accrual Approach are triggered by LAT based on contract payment terms (posting performed when expense is incurred - similar to GR)
C31: All amounts below are in contract currency (DC)
C32: Please check LC2, LC3 FX posting conversion where applicable | J32: Lease payment per period (excl. VAT) | L32: 250
F33: SAP Posting date | J33: Payment frequency | L33: Monthly
C34: Description | F34: P7 | H34: P8 | J34: Payment timing | L34: Advance
C35: Payment by Nakisa | E35: 1 | F35: 43678 | G35: 5 | H35: 43678 | J35: First payment Date | L35: 43647
C36: Invoice booking | E36: 2 | F36: 43647 | G36: 6 | H36: 43678 | J36: Lease term (months) | L36: 24
C37: Automated reposting of Invoice | E37: 3 | F37: 43647 | G37: 7 | H37: 43678 | J37: Lease start date | L37: 43647
C38: Monthly Lease expense posting | E38: 4 | F38: 43678 | G38: 8 | H38: 43708 | J38: Lease end date | L38: 44377
C41: Lease expense - FurnFx Stat/Tax (534065) | H41: Prepaid Lease Cost (167021)
C42: 4 | D42: =J42 -> 250 | H42: 1 | I42: =E47 -> 250 | J42: =L32 -> 250 | K42: 4
C43: 8 | D43: =J43 -> 250 | H43: 5 | I43: =E48 -> 250 | J43: =L32 -> 250 | K43: 8
C46: Invoice Clearing Leasing (243031) | H46: Invoice Clearing Leasing - Technical (243032)
C47: 3 | D47: =J47 -> 250 | E47: =L32 -> 250 | F47: 1 | H47: 2 | I47: =E52-I52 -> 250 | J47: =L32 -> 250 | K47: 3
C48: 7 | D48: =J48 -> 250 | E48: =L32 -> 250 | F48: 5 | H48: 6 | I48: =E53-I52 -> 250 | J48: =L32 -> 250 | K48: 7
C51: Accounts Payable* | H51: Input VAT (example - different by entity)
E52: 300 | F52: 2 | H52: 2 | I52: 50
E53: 300 | F53: 6 | H53: 6 | I53: 50
C59: Invoice Receipt Approach
C60: Lease expense recognition for IR approach is triggered by the invoice posting
...

Sheet 3 - Short Term Contract
C1: 3 - Short Term Contract (non-recoverable VAT) | BB1: Advance
C3: IFRS 16 Approach
C4: All amounts below are in contract currency (DC)
C5: Please check LC2, LC3 FX posting conversion where applicable | J5: Lease payment per period | L5: 5000
F6: SAP Posting date | J6: Payment frequency | L6: Monthly
C7: Description | F7: P7 | H7: P8 | J7: Payment timing | L7: Advance
C8: Payment by Nakisa | E8: 1 | F8: 43647 | G8: 5 | H8: 43678 | J8: First payment Date | L8: 43647
C9: AP: invoice booking | E9: 2 | F9: 43647 | G9: 6 | H9: 43678 | J9: Lease term (months) | L9: 9
